Workbook

Sheet Sep
A1: location | B1: date | C1: reserved_at | D1: appointment_type | E1: status | F1: first_name | G1: last_name | H1: address_line_1 | I1: address_line_2 | J1: address_line_3 | K1: address_line_4 | L1: address_line_5 | M1: Postcode | N1: Email | O1: sex_at_birth | P1: dob | Q1: Age | R1: reference | S1: phone | T1: product_code | U1: extra_product_options | V1: totals | W1: process_status | X1: tags | Y1: FHM_Identifier | Z1: patient_id_number_prefix | AA1: single_use_invitation_code | AB1: postcode_region | AC1: Prefix | AD1: Region | AE1: Corporate Or Self Pay
A2: LIH | B2: 45670 | C2: 45660 | D2: screening | E2: Booked | F2: Valentin | G2: Elsip | H2: 80749 Washington Junction | I2: Room 1862 | M2: IG9 6EL | N2: velsip0@microsoft.com | O2: male | P2: 27157 | Q2: =DATEDIF(P2,B2,"Y") -> 50 | R2: F10FAFDF | S2: 447799822636 | T2: Advanced | V2: {=IFERROR( _xlfn.XLOOKUP(1, (tblPrices[Prefix]=$AC2)*(tblPrices[Product Code]=$T2), tblPrices[Price] ), 0 ) + IF(ISNUMBER(SEARCH("Mammogram",$U2)), IFERROR(_xlfn.XLOOKUP(1,(tblPrices[Prefix]=$AC2)*(tblPrices[Product Code]="Mammogram"),tblPrices[Price]),0), 0 ) + IF(ISNUMBER(SEARCH("PSA",$U2)), IFERROR(_xlfn.XLOOKUP(1,(tblPrices[Prefix]=$AC2)*(tblPrices[Product Code]="PSA"),tblPrices[Price]),0), 0 )} -> 543.38 | W2: dispatched | X2: paid,fasting,online,viewed_online | Z2: 19485502 | AA2: U48 | AB2: {=_xlfn.LET(_xlpm.pc, UPPER(TRIM(M2)), LEFT(_xlpm.pc, MIN(FIND({0,1,2,3,4,5,6,7,8,9}, _xlpm.pc&"0123456789"))-1))} -> IG | AC2: U48 | AD2: =VLOOKUP(AB2, postcode_table!A:B, 2, FALSE) -> Ilford | AE2: =IFERROR(_xlfn.XLOOKUP(AC2, price_lookup_table!$C:$C, price_lookup_table!$B:$B), "") -> Corporate
A3: MNR | B3: 45670 | C3: 45666 | D3: screening | E3: Booked | F3: Carlin | G3: Towson | H3: 2 Rieder Center | I3: Apt 153 | M3: MK44 3HD | N3: ctowson1@aboutads.info | O3: male | P3: 26347 | Q3: =DATEDIF(P3,B3,"Y") -> 52 | R3: 8B53BEB1 | S3: 447831777666 | T3: Advanced | V3: {=IFERROR( _xlfn.XLOOKUP(1, (tblPrices[Prefix]=$AC3)*(tblPrices[Product Code]=$T3), tblPrices[Price] ), 0 ) + IF(ISNUMBER(SEARCH("Mammogram",$U3)), IFERROR(_xlfn.XLOOKUP(1,(tblPrices[Prefix]=$AC3)*(tblPrices[Product Code]="Mammogram"),tblPrices[Price]),0), 0 ) + IF(ISNUMBER(SEARCH("PSA",$U3)), IFERROR(_xlfn.XLOOKUP(1,(tblPrices[Prefix]=$AC3)*(tblPrices[Product Code]="PSA"),tblPrices[Price]),0), 0 )} -> 543.38 | W3: dispatched | X3: paid,fasting,green,online,ecg_uploaded | Z3: 12267863 | AA3: U48 | AB3: {=_xlfn.LET(_xlpm.pc, UPPER(TRIM(M3)), LEFT(_xlpm.pc, MIN(FIND({0,1,2,3,4,5,6,7,8,9}, _xlpm.pc&"0123456789"))-1))} -> MK | AC3: U48 | AD3: =VLOOKUP(AB3, postcode_table!A:B, 2, FALSE) -> Milton Keynes | AE3: =IFERROR(_xlfn.XLOOKUP(AC3, price_lookup_table!$C:$C, price_lookup_table!$B:$B), "") -> Corporate
A4: LIH | B4: 45670 | C4: 45660 | D4: screening | E4: Booked | F4: Woodie | G4: Kynsey | H4: 5418 Debra Court | I4: PO Box 20094 | M4: SE3 8BP | N4: wkynsey2@squidoo.com | O4: male | P4: 29270 | Q4: =DATEDIF(P4,B4,"Y") -> 44 | R4: CD77C3D1 | S4: 447766258553 | T4: Advanced | V4: {=IFERROR( _xlfn.XLOOKUP(1, (tblPrices[Prefix]=$AC4)*(tblPrices[Product Code]=$T4), tblPrices[Price] ), 0 ) + IF(ISNUMBER(SEARCH("Mammogram",$U4)), IFERROR(_xlfn.XLOOKUP(1,(tblPrices[Prefix]=$AC4)*(tblPrices[Product Code]="Mammogram"),tblPrices[Price]),0), 0 ) + IF(ISNUMBER(SEARCH("PSA",$U4)), IFERROR(_xlfn.XLOOKUP(1,(tblPrices[Prefix]=$AC4)*(tblPrices[Product Code]="PSA"),tblPrices[Price]),0), 0 )} -> 543.38 | W4: dispatched | X4: paid,fasting,online,viewed_online | Z4: 22003492 | AA4: U48 | AB4: {=_xlfn.LET(_xlpm.pc, UPPER(TRIM(M4)), LEFT(_xlpm.pc, MIN(FIND({0,1,2,3,4,5,6,7,8,9}, _xlpm.pc&"0123456789"))-1))} -> SE | AC4: U48 | AD4: =VLOOKUP(AB4, postcode_table!A:B, 2, FALSE) -> South East London | AE4: =IFERROR(_xlfn.XLOOKUP(AC4, price_lookup_table!$C:$C, price_lookup_table!$B:$B), "") -> Corporate
A5: GAR | B5: 45671 | C5: 45660 | D5: screening | E5: Booked | F5: Randal | G5: Fisk | H5: 3 Waxwing Pass | I5: Apt 382 | M5: N20 0RH | N5: rfisk3@mashable.com | O5: female | P5: 27760 | Q5: =DATEDIF(P5,B5,"Y") -> 49 | R5: 74C623C0 | S5: 447841131185 | T5: Select | V5: {=IFERROR( _xlfn.XLOOKUP(1, (tblPrices[Prefix]=$AC5)*(tblPrices[Product Code]=$T5), tblPrices[Price] ), 0 ) + IF(ISNUMBER(SEARCH("Mammogram",$U5)), IFERROR(_xlfn.XLOOKUP(1,(tblPrices[Prefix]=$AC5)*(tblPrices[Product Code]="Mammogram"),tblPrices[Price]),0), 0 ) + IF(ISNUMBER(SEARCH("PSA",$U5)), IFERROR(_xlfn.XLOOKUP(1,(tblPrices[Prefix]=$AC5)*(tblPrices[Product Code]="PSA"),tblPrices[Price]),0), 0 )} -> 357.38 | W5: dispatched | X5: paid,fasting,amber,online,viewed_online | Z5: 21689026 | AA5: U48 | AB5: {=_xlfn.LET(_xlpm.pc, UPPER(TRIM(M5)), LEFT(_xlpm.pc, MIN(FIND({0,1,2,3,4,5,6,7,8,9}, _xlpm.pc&"0123456789"))-1))} -> N | AC5: U48 | AD5: =VLOOKUP(AB5, postcode_table!A:B, 2, FALSE) -> North London | AE5: =IFERROR(_xlfn.XLOOKUP(AC5, price_lookup_table!$C:$C, price_lookup_table!$B:$B), "") -> Corporate
A6: GAR | B6: 45672 | C6: 45665 | D6: screening | E6: Booked | F6: Marie-ann | G6: Trathen | H6: 73 Vernon Junction | I6: Room 1463 | M6: NW3 4BY | N6: mtrathen4@howstuffworks.com | O6: female | P6: 25543 | Q6: =DATEDIF(P6,B6,"Y") -> 55 | R6: B5B724D4 | S6: 447943299012 | T6: Advanced | U6: MAMMOGRAM | V6: {=IFERROR( _xlfn.XLOOKUP(1, (tblPrices[Prefix]=$AC6)*(tblPrices[Product Code]=$T6), tblPrices[Price] ), 0 ) + IF(ISNUMBER(SEARCH("Mammogram",$U6)), IFERROR(_xlfn.XLOOKUP(1,(tblPrices[Prefix]=$AC6)*(tblPrices[Product Code]="Mammogram"),tblPrices[Price]),0), 0 ) + IF(ISNUMBER(SEARCH("PSA",$U6)), IFERROR(_xlfn.XLOOKUP(1,(tblPrices[Prefix]=$AC6)*(tblPrices[Product Code]="PSA"),tblPrices[Price]),0), 0 )} -> 690.38 | W6: dispatched | X6: paid,fasting,green,online,viewed_online | Z6: 22008182 | AA6: U48 | AB6: {=_xlfn.LET(_xlpm.pc, UPPER(TRIM(M6)), LEFT(_xlpm.pc, MIN(FIND({0,1,2,3,4,5,6,7,8,9}, _xlpm.pc&"0123456789"))-1))} -> NW | AC6: U48 | AD6: =VLOOKUP(AB6, postcode_table!A:B, 2, FALSE) -> North West London | AE6: =IFERROR(_xlfn.XLOOKUP(AC6, price_lookup_table!$C:$C, price_lookup_table!$B:$B), "") -> Corporate
A7: ALB | B7: 45674 | C7: 45663 | D7: screening | E7: Booked | F7: Siusan | G7: Baskerville | H7: 724 Darwin Junction | I7: PO Box 56845 | M7: AB41 6EE | N7: sbaskerville5@ask.com | O7: male | P7: 32886 | Q7: =DATEDIF(P7,B7,"Y") -> 35 | R7: D202EE3A | S7: 447826541608 | T7: Advanced | V7: {=IFERROR( _xlfn.XLOOKUP(1, (tblPrices[Prefix]=$AC7)*(tblPrices[Product Code]=$T7), tblPrices[Price] ), 0 ) + IF(ISNUMBER(SEARCH("Mammogram",$U7)), IFERROR(_xlfn.XLOOKUP(1,(tblPrices[Prefix]=$AC7)*(tblPrices[Product Code]="Mammogram"),tblPrices[Price]),0), 0 ) + IF(ISNUMBER(SEARCH("PSA",$U7)), IFERROR(_xlfn.XLOOKUP(1,(tblPrices[Prefix]=$AC7)*(tblPrices[Product Code]="PSA"),tblPrices[Price]),0), 0 )} -> 543.38 | W7: dispatched | X7: paid,fasting,online,viewed_online | Z7: 15859179 | AA7: U48 | AB7: {=_xlfn.LET(_xlpm.pc, UPPER(TRIM(M7)), LEFT(_xlpm.pc, MIN(FIND({0,1,2,3,4,5,6,7,8,9}, _xlpm.pc&"0123456789"))-1))} -> AB | AC7: U48 | AD7: =VLOOKUP(AB7, postcode_table!A:B, 2, FALSE) -> Aberdeen | AE7: =IFERROR(_xlfn.XLOOKUP(AC7, price_lookup_table!$C:$C, price_lookup_table!$B:$B), "") -> Corporate
A8: SYC | B8: 45674 | C8: 45663 | D8: screening | E8: Booked | F8: Seth | G8: Witherup | H8: 993 Cherokee Junction | I8: Room 1765 | M8: W8 4SB | N8: switherup6@zimbio.com | O8: male | P8: 28631 | Q8: =DATEDIF(P8,B8,"Y") -> 46 | R8: F5064A01 | S8: 447794842337 | T8: Select | U8: PSA | V8: {=IFERROR( _xlfn.XLOOKUP(1, (tblPrices[Prefix]=$AC8)*(tblPrices[Product Code]=$T8), tblPrices[Price] ), 0 ) + IF(ISNUMBER(SEARCH("Mammogram",$U8)), IFERROR(_xlfn.XLOOKUP(1,(tblPrices[Prefix]=$AC8)*(tblPrices[Product Code]="Mammogram"),tblPrices[Price]),0), 0 ) + IF(ISNUMBER(SEARCH("PSA",$U8)), IFERROR(_xlfn.XLOOKUP(1,(tblPrices[Prefix]=$AC8)*(tblPrices[Product Code]="PSA"),tblPrices[Price]),0), 0 )} -> 469.38 | W8: dispatched | X8: viewed_online,paid,fasting,amber,online | Z8: 22005952 | AA8: U48 | AB8: {=_xlfn.LET(_xlpm.pc, UPPER(TRIM(M8)), LEFT(_xlpm.pc, MIN(FIND({0,1,2,3,4,5,6,7,8,9}, _xlpm.pc&"0123456789"))-1))} -> W | AC8: U48 | AD8: =VLOOKUP(AB8, postcode_table!A:B, 2, FALSE) -> West London | AE8: =IFERROR(_xlfn.XLOOKUP(AC8, price_lookup_table!$C:$C, price_lookup_table!$B:$B), "") -> Corporate
A9: LIN | B9: 45674 | C9: 45664 | D9: screening | E9: Booked | F9: Harry | G9: Yakunchikov | H9: 59 Michigan Hill | I9: Apt 219 | M9: LN10 6PJ | N9: hyakunchikov7@google.es | O9: male | P9: 20340 | Q9: =DATEDIF(P9,B9,"Y") -> 69 | R9: BD65DBE9 | S9: 447709012401 | T9: Advanced | V9: {=IFERROR( _xlfn.XLOOKUP(1, (tblPrices[Prefix]=$AC9)*(tblPrices[Product Code]=$T9), tblPrices[Price] ), 0 ) + IF(ISNUMBER(SEARCH("Mammogram",$U9)), IFERROR(_xlfn.XLOOKUP(1,(tblPrices[Prefix]=$AC9)*(tblPrices[Product Code]="Mammogram"),tblPrices[Price]),0), 0 ) + IF(ISNUMBER(SEARCH("PSA",$U9)), IFERROR(_xlfn.XLOOKUP(1,(tblPrices[Prefix]=$AC9)*(tblPrices[Product Code]="PSA"),tblPrices[Price]),0), 0 )} -> 543.38 | W9: dispatched | X9: paid,fasting,amber,online,viewed_online | Z9: 22007274 | AA9: U48 | AB9: {=_xlfn.LET(_xlpm.pc, UPPER(TRIM(M9)), LEFT(_xlpm.pc, MIN(FIND({0,1,2,3,4,5,6,7,8,9}, _xlpm.pc&"0123456789"))-1))} -> LN | AC9: U48 | AD9: =VLOOKUP(AB9, postcode_table!A:B, 2, FALSE) -> Lincoln | AE9: =IFERROR(_xlfn.XLOOKUP(AC9, price_lookup_table!$C:$C, price_lookup_table!$B:$B), "") -> Corporate
A10: LIH | B10: 45677 | C10: 45660 | D10: screening | E10: Booked | F10: Ferd | G10: Poleye | H10: 0 Melody Road | I10: Room 1024 | M10: KT2 7BS | N10: fpoleye8@techcrunch.com | O10: female | P10: 28703 | Q10: =DATEDIF(P10,B10,"Y") -> 46 | R10: ACF2F7EB | S10: 447740375131 | T10: Advanced | V10: {=IFERROR( _xlfn.XLOOKUP(1, (tblPrices[Prefix]=$AC10)*(tblPrices[Product Code]=$T10), tblPrices[Price] ), 0 ) + IF(ISNUMBER(SEARCH("Mammogram",$U10)), IFERROR(_xlfn.XLOOKUP(1,(tblPrices[Prefix]=$AC10)*(tblPrices[Product Code]="Mammogram"),tblPrices[Price]),0), 0 ) + IF(ISNUMBER(SEARCH("PSA",$U10)), IFERROR(_xlfn.XLOOKUP(1,(tblPrices[Prefix]=$AC10)*(tblPrices[Product Code]="PSA"),tblPrices[Price]),0), 0 )} -> 543.38 | W10: dispatched | X10: viewed_online,paid,fasting,online | Z10: 22003219 | AA10: U48 | AB10: {=_xlfn.LET(_xlpm.pc, UPPER(TRIM(M10)), LEFT(_xlpm.pc, MIN(FIND({0,1,2,3,4,5,6,7,8,9}, _xlpm.pc&"0123456789"))-1))} -> KT | AC10: U48 | AD10: =VLOOKUP(AB10, postcode_table!A:B, 2, FALSE) -> Kingston upon Thames | AE10: =IFERROR(_xlfn.XLOOKUP(AC10, price_lookup_table!$C:$C, price_lookup_table!$B:$B), "") -> Corporate
A11: LIH | B11: 45677 | C11: 45663 | D11: screening | E11: Booked | F11: Garvey | G11: Spurrett | H11: 87662 Express Parkway | I11: Apt 608 | M11: N16 8BF | N11: gspurrett9@ucoz.ru | O11: male | P11: 21925 | Q11: =DATEDIF(P11,B11,"Y") -> 65 | R11: E999EE4D | S11: 447414893831 | T11: Advanced | V11: {=IFERROR( _xlfn.XLOOKUP(1, (tblPrices[Prefix]=$AC11)*(tblPrices[Product Code]=$T11), tblPrices[Price] ), 0 ) + IF(ISNUMBER(SEARCH("Mammogram",$U11)), IFERROR(_xlfn.XLOOKUP(1,(tblPrices[Prefix]=$AC11)*(tblPrices[Product Code]="Mammogram"),tblPrices[Price]),0), 0 ) + IF(ISNUMBER(SEARCH("PSA",$U11)), IFERROR(_xlfn.XLOOKUP(1,(tblPrices[Prefix]=$AC11)*(tblPrices[Product Code]="PSA"),tblPrices[Price]),0), 0 )} -> 543.38 | W11: dispatched | X11: paid,fasting,online,viewed_online | Z11: 22005957 | AA11: U48 | AB11: {=_xlfn.LET(_xlpm.pc, UPPER(TRIM(M11)), LEFT(_xlpm.pc, MIN(FIND({0,1,2,3,4,5,6,7,8,9}, _xlpm.pc&"0123456789"))-1))} -> N | AC11: U48 | AD11: =VLOOKUP(AB11, postcode_table!A:B, 2, FALSE) -> North London | AE11: =IFERROR(_xlfn.XLOOKUP(AC11, price_lookup_table!$C:$C, price_lookup_table!$B:$B), "") -> Corporate
A12: PRI | B12: 45677 | C12: 45659 | D12: screening | E12: Booked | F12: Carlina | G12: Danielut | H12: 18 Larry Trail | I12: Suite 70 | M12: HR9 7JZ | N12: cdanieluta@cam.ac.uk | O12: male | P12: 34860 | Q12: =DATEDIF(P12,B12,"Y") -> 29 | R12: B5D49A8D | S12: 447787576459 | T12: Advanced Plus | V12: {=IFERROR( _xlfn.XLOOKUP(1, (tblPrices[Prefix]=$AC12)*(tblPrices[Product Code]=$T12), tblPrices[Price] ), 0 ) + IF(ISNUMBER(SEARCH("Mammogram",$U12)), IFERROR(_xlfn.XLOOKUP(1,(tblPrices[Prefix]=$AC12)*(tblPrices[Product Code]="Mammogram"),tblPrices[Price]),0), 0 ) + IF(ISNUMBER(SEARCH("PSA",$U12)), IFERROR(_xlfn.XLOOKUP(1,(tblPrices[Prefix]=$AC12)*(tblPrices[Product Code]="PSA"),tblPrices[Price]),0), 0 )} -> 727.88 | W12: dispatched | X12: paid,fasting,online,viewed_online | Z12: 21517809 | AA12: U48 | AB12: {=_xlfn.LET(_xlpm.pc, UPPER(TRIM(M12)), LEFT(_xlpm.pc, MIN(FIND({0,1,2,3,4,5,6,7,8,9}, _xlpm.pc&"0123456789"))-1))} -> HR | AC12: U48 | AD12: =VLOOKUP(AB12, postcode_table!A:B, 2, FALSE) -> Hereford | AE12: =IFERROR(_xlfn.XLOOKUP(AC12, price_lookup_table!$C:$C, price_lookup_table!$B:$B), "") -> Corporate
A13: BSE | B13: 45678 | C13: 45660 | D13: screening | E13: Booked | F13: Drew | G13: Nollet | H13: 82103 Kipling Trail | I13: Room 278 | M13: CO5 0PX | N13: dnolletb@hc360.com | O13: female | P13: 34065 | Q13: =DATEDIF(P13,B13,"Y") -> 31 | R13: 750DF5E6 | S13: 447803127114 | T13: Advanced | V13: {=IFERROR( _xlfn.XLOOKUP(1, (tblPrices[Prefix]=$AC13)*(tblPrices[Product Code]=$T13), tblPrices[Price] ), 0 ) + IF(ISNUMBER(SEARCH("Mammogram",$U13)), IFERROR(_xlfn.XLOOKUP(1,(tblPrices[Prefix]=$AC13)*(tblPrices[Product Code]="Mammogram"),tblPrices[Price]),0), 0 ) + IF(ISNUMBER(SEARCH("PSA",$U13)), IFERROR(_xlfn.XLOOKUP(1,(tblPrices[Prefix]=$AC13)*(tblPrices[Product Code]="PSA"),tblPrices[Price]),0), 0 )} -> 543.38 | W13: dispatched | X13: paid,fasting,online,viewed_online | Z13: 22003689 | AA13: U48 | AB13: {=_xlfn.LET(_xlpm.pc, UPPER(TRIM(M13)), LEFT(_xlpm.pc, MIN(FIND({0,1,2,3,4,5,6,7,8,9}, _xlpm.pc&"0123456789"))-1))} -> CO | AC13: U48 | AD13: =VLOOKUP(AB13, postcode_table!A:B, 2, FALSE) -> Colchester | AE13: =IFERROR(_xlfn.XLOOKUP(AC13, price_lookup_table!$C:$C, price_lookup_table!$B:$B), "") -> Corporate
A14: BSE | B14: 45678 | C14: 45660 | D14: screening | E14: Booked | F14: Man | G14: De la Yglesia | H14: 83 Holy Cross Lane | I14: PO Box 99290 | M14: CO5 0PX | N14: mdelayglesiac@eepurl.com | O14: male | P14: 23477 | Q14: =DATEDIF(P14,B14,"Y") -> 60 | R14: 94F3FC73 | S14: 447713247692 | T14: Advanced | V14: {=IFERROR( _xlfn.XLOOKUP(1, (tblPrices[Prefix]=$AC14)*(tblPrices[Product Code]=$T14), tblPrices[Price] ), 0 ) + IF(ISNUMBER(SEARCH("Mammogram",$U14)), IFERROR(_xlfn.XLOOKUP(1,(tblPrices[Prefix]=$AC14)*(tblPrices[Product Code]="Mammogram"),tblPrices[Price]),0), 0 ) + IF(ISNUMBER(SEARCH("PSA",$U14)), IFERROR(_xlfn.XLOOKUP(1,(tblPrices[Prefix]=$AC14)*(tblPrices[Product Code]="PSA"),tblPrices[Price]),0), 0 )} -> 543.38 | W14: dispatched | X14: paid,fasting,online,viewed_online | Z14: 22003455 | AA14: U48 | AB14: {=_xlfn.LET(_xlpm.pc, UPPER(TRIM(M14)), LEFT(_xlpm.pc, MIN(FIND({0,1,2,3,4,5,6,7,8,9}, _xlpm.pc&"0123456789"))-1))} -> CO | AC14: U48 | AD14: =VLOOKUP(AB14, postcode_table!A:B, 2, FALSE) -> Colchester | AE14: =IFERROR(_xlfn.XLOOKUP(AC14, price_lookup_table!$C:$C, price_lookup_table!$B:$B), "") -> Corporate
A15: PRI | B15: 45678 | C15: 45670 | D15: screening | E15: Booked | F15: Munmro | G15: Malden | H15: 90 Katie Way | I15: Apt 1246 | M15: GL56 0QT | N15: mmaldend@istockphoto.com | O15: male | P15: 26045 | Q15: =DATEDIF(P15,B15,"Y") -> 53 | R15: 0C9E6F5F | S15: 447880598096 | T15: Advanced | V15: {=IFERROR( _xlfn.XLOOKUP(1, (tblPrices[Prefix]=$AC15)*(tblPrices[Product Code]=$T15), tblPrices[Price] ), 0 ) + IF(ISNUMBER(SEARCH("Mammogram",$U15)), IFERROR(_xlfn.XLOOKUP(1,(tblPrices[Prefix]=$AC15)*(tblPrices[Product Code]="Mammogram"),tblPrices[Price]),0), 0 ) + IF(ISNUMBER(SEARCH("PSA",$U15)), IFERROR(_xlfn.XLOOKUP(1,(tblPrices[Prefix]=$AC15)*(tblPrices[Product Code]="PSA"),tblPrices[Price]),0), 0 )} -> 543.38 | W15: dispatched | X15: rescheduled,paid,fasting,online,viewed_online | Z15: 22007131 | AA15: U48 | AB15: {=_xlfn.LET(_xlpm.pc, UPPER(TRIM(M15)), LEFT(_xlpm.pc, MIN(FIND({0,1,2,3,4,5,6,7,8,9}, _xlpm.pc&"0123456789"))-1))} -> GL | AC15: U48 | AD15: =VLOOKUP(AB15, postcode_table!A:B, 2, FALSE) -> Gloucester | AE15: =IFERROR(_xlfn.XLOOKUP(AC15, price_lookup_table!$C:$C, price_lookup_table!$B:$B), "") -> Corporate
A16: ALV | B16: 45678 | C16: 45670 | D16: screening | E16: Booked | F16: Alli | G16: Jozsika | H16: 00 Sachtjen Terrace | I16: Apt 116 | M16: GU1 2SJ | N16: ajozsikae@youtu.be | O16: female | P16: 16035 | Q16: =DATEDIF(P16,B16,"Y") -> 81 | R16: A9E8B973 | S16: 447523844064 | T16: Essential | V16: {=IFERROR( _xlfn.XLOOKUP(1, (tblPrices[Prefix]=$AC16)*(tblPrices[Product Code]=$T16), tblPrices[Price] ), 0 ) + IF(ISNUMBER(SEARCH("Mammogram",$U16)), IFERROR(_xlfn.XLOOKUP(1,(tblPrices[Prefix]=$AC16)*(tblPrices[Product Code]="Mammogram"),tblPrices[Price]),0), 0 ) + IF(ISNUMBER(SEARCH("PSA",$U16)), IFERROR(_xlfn.XLOOKUP(1,(tblPrices[Prefix]=$AC16)*(tblPrices[Product Code]="PSA"),tblPrices[Price]),0), 0 )} -> 246 | W16: dispatched | X16: paid,phone_call_required,fasting,online,viewed_online | Z16: 22014220 | AA16: M01Phone | AB16: {=_xlfn.LET(_xlpm.pc, UPPER(TRIM(M16)), LEFT(_xlpm.pc, MIN(FIND({0,1,2,3,4,5,6,7,8,9}, _xlpm.pc&"0123456789"))-1))} -> GU | AC16: =LEFT(AA16, 3) -> M01 | AD16: =VLOOKUP(AB16, postcode_table!A:B, 2, FALSE) -> Guildford | AE16: =IFERROR(_xlfn.XLOOKUP(AC16, price_lookup_table!$C:$C, price_lookup_table!$B:$B), "") -> Self Pay
A17: ALX | B17: 45678 | C17: 45670 | D17: screening | E17: Booked | F17: Flossy | G17: Osban | H17: 97648 Forest Dale Parkway | I17: Suite 89 | M17: M40 8BW | N17: fosbanf@surveymonkey.com | O17: male | P17: 27129 | Q17: =DATEDIF(P17,B17,"Y") -> 50 | R17: 1AAAB80A | S17: 447920884410 | T17: Essential | V17: {=IFERROR( _xlfn.XLOOKUP(1, (tblPrices[Prefix]=$AC17)*(tblPrices[Product Code]=$T17), tblPrices[Price] ), 0 ) + IF(ISNUMBER(SEARCH("Mammogram",$U17)), IFERROR(_xlfn.XLOOKUP(1,(tblPrices[Prefix]=$AC17)*(tblPrices[Product Code]="Mammogram"),tblPrices[Price]),0), 0 ) + IF(ISNUMBER(SEARCH("PSA",$U17)), IFERROR(_xlfn.XLOOKUP(1,(tblPrices[Prefix]=$AC17)*(tblPrices[Product Code]="PSA"),tblPrices[Price]),0), 0 )} -> 246 | W17: dispatched | X17: rescheduled,paid,fasting,online,viewed_online | Z17: 22008655 | AA17: M01Phone | AB17: {=_xlfn.LET(_xlpm.pc, UPPER(TRIM(M17)), LEFT(_xlpm.pc, MIN(FIND({0,1,2,3,4,5,6,7,8,9}, _xlpm.pc&"0123456789"))-1))} -> M | AC17: =LEFT(AA17, 3) -> M01 | AD17: =VLOOKUP(AB17, postcode_table!A:B, 2, FALSE) -> Manchester | AE17: =IFERROR(_xlfn.XLOOKUP(AC17, price_lookup_table!$C:$C, price_lookup_table!$B:$B), "") -> Self Pay
A18: LIH | B18: 45679 | C18: 45660 | D18: screening | E18: Booked | F18: Felic | G18: Sparshutt | H18: 2 Park Meadow Lane | I18: Suite 94 | M18: E1 5FZ | N18: fsparshuttg@wsj.com | O18: male | P18: 35387 | Q18: =DATEDIF(P18,B18,"Y") -> 28 | R18: AA32E553 | S18: 447798893954 | T18: Advanced | V18: {=IFERROR( _xlfn.XLOOKUP(1, (tblPrices[Prefix]=$AC18)*(tblPrices[Product Code]=$T18), tblPrices[Price] ), 0 ) + IF(ISNUMBER(SEARCH("Mammogram",$U18)), IFERROR(_xlfn.XLOOKUP(1,(tblPrices[Prefix]=$AC18)*(tblPrices[Product Code]="Mammogram"),tblPrices[Price]),0), 0 ) + IF(ISNUMBER(SEARCH("PSA",$U18)), IFERROR(_xlfn.XLOOKUP(1,(tblPrices[Prefix]=$AC18)*(tblPrices[Product Code]="PSA"),tblPrices[Price]),0), 0 )} -> 543 | W18: dispatched | X18: paid,fasting,online,viewed_online | Z18: 22002551 | AA18: AXAMEMBER | AB18: {=_xlfn.LET(_xlpm.pc, UPPER(TRIM(M18)), LEFT(_xlpm.pc, MIN(FIND({0,1,2,3,4,5,6,7,8,9}, _xlpm.pc&"0123456789"))-1))} -> E | AC18: =LEFT(AA18, 3) -> AXA | AD18: =VLOOKUP(AB18, postcode_table!A:B, 2, FALSE) -> East London | AE18: =IFERROR(_xlfn.XLOOKUP(AC18, price_lookup_table!$C:$C, price_lookup_table!$B:$B), "") -> Self Pay
A19: LIH | B19: 45679 | C19: 45667 | D19: screening | E19: Booked | F19: Vince | G19: Stoyle | H19: 6 Truax Crossing | I19: PO Box 88818 | M19: SE10 8AS | N19: vstoyleh@typepad.com | O19: male | P19: 27524 | Q19: =DATEDIF(P19,B19,"Y") -> 49 | R19: 7E600672 | S19: 447826855190 | T19: Advanced | V19: {=IFERROR( _xlfn.XLOOKUP(1, (tblPrices[Prefix]=$AC19)*(tblPrices[Product Code]=$T19), tblPrices[Price] ), 0 ) + IF(ISNUMBER(SEARCH("Mammogram",$U19)), IFERROR(_xlfn.XLOOKUP(1,(tblPrices[Prefix]=$AC19)*(tblPrices[Product Code]="Mammogram"),tblPrices[Price]),0), 0 ) + IF(ISNUMBER(SEARCH("PSA",$U19)), IFERROR(_xlfn.XLOOKUP(1,(tblPrices[Prefix]=$AC19)*(tblPrices[Product Code]="PSA"),tblPrices[Price]),0), 0 )} -> 543 | W19: dispatched | X19: rescheduled,paid,fasting,online,viewed_online | Z19: 21159036 | AA19: AXAMEMBER | AB19: {=_xlfn.LET(_xlpm.pc, UPPER(TRIM(M19)), LEFT(_xlpm.pc, MIN(FIND({0,1,2,3,4,5,6,7,8,9}, _xlpm.pc&"0123456789"))-1))} -> SE | AC19: =LEFT(AA19, 3) -> AXA | AD19: =VLOOKUP(AB19, postcode_table!A:B, 2, FALSE) -> South East London | AE19: =IFERROR(_xlfn.XLOOKUP(AC19, price_lookup_table!$C:$C, price_lookup_table!$B:$B), "") -> Self Pay
A20: SYC | B20: 45679 | C20: 45659 | D20: screening | E20: Booked | F20: Ulrick | G20: Swedeland | H20: 71132 Nobel Road | I20: PO Box 84101 | M20: SW6 6QA | N20: uswedelandi@sciencedaily.com | O20: male | P20: 17343 | Q20: =DATEDIF(P20,B20,"Y") -> 77 | R20: 13090BEF | S20: 447436338092 | T20: Advanced | V20: {=IFERROR( _xlfn.XLOOKUP(1, (tblPrices[Prefix]=$AC20)*(tblPrices[Product Code]=$T20), tblPrices[Price] ), 0 ) + IF(ISNUMBER(SEARCH("Mammogram",$U20)), IFERROR(_xlfn.XLOOKUP(1,(tblPrices[Prefix]=$AC20)*(tblPrices[Product Code]="Mammogram"),tblPrices[Price]),0), 0 ) + IF(ISNUMBER(SEARCH("PSA",$U20)), IFERROR(_xlfn.XLOOKUP(1,(tblPrices[Prefix]=$AC20)*(tblPrices[Product Code]="PSA"),tblPrices[Price]),0), 0 )} -> 543 | W20: dispatched | X20: paid,fasting,online,viewed_online | Z20: 22001140 | AA20: AXAMEMBER | AB20: {=_xlfn.LET(_xlpm.pc, UPPER(TRIM(M20)), LEFT(_xlpm.pc, MIN(FIND({0,1,2,3,4,5,6,7,8,9}, _xlpm.pc&"0123456789"))-1))} -> SW | AC20: =LEFT(AA20, 3) -> AXA | AD20: =VLOOKUP(AB20, postcode_table!A:B, 2, FALSE) -> South West London | AE20: =IFERROR(_xlfn.XLOOKUP(AC20, price_lookup_table!$C:$C, price_lookup_table!$B:$B), "") -> Self Pay
A21: BTH | B21: 45679 | C21: 45670 | D21: screening | E21: Booked | F21: Georgine | G21: Berre | H21: 26 Fordem Junction | I21: 1st Floor | M21: BA1 2PH | N21: gberrej@wired.com | O21: female | P21: 24020 | Q21: =DATEDIF(P21,B21,"Y") -> 59 | R21: 59DB436B | S21: 447810810402 | T21: Advanced | V21: {=IFERROR( _xlfn.XLOOKUP(1, (tblPrices[Prefix]=$AC21)*(tblPrices[Product Code]=$T21), tblPrices[Price] ), 0 ) + IF(ISNUMBER(SEARCH("Mammogram",$U21)), IFERROR(_xlfn.XLOOKUP(1,(tblPrices[Prefix]=$AC21)*(tblPrices[Product Code]="Mammogram"),tblPrices[Price]),0), 0 ) + IF(ISNUMBER(SEARCH("PSA",$U21)), IFERROR(_xlfn.XLOOKUP(1,(tblPrices[Prefix]=$AC21)*(tblPrices[Product Code]="PSA"),tblPrices[Price]),0), 0 )} -> 724.5 | W21: dispatched | X21: viewed_online,paid,fasting,online,ecg_uploaded | Z21: 20941152 | AA21: M01Phone | AB21: {=_xlfn.LET(_xlpm.pc, UPPER(TRIM(M21)), LEFT(_xlpm.pc, MIN(FIND({0,1,2,3,4,5,6,7,8,9}, _xlpm.pc&"0123456789"))-1))} -> BA | AC21: =LEFT(AA21, 3) -> M01 | AD21: =VLOOKUP(AB21, postcode_table!A:B, 2, FALSE) -> Bath | AE21: =IFERROR(_xlfn.XLOOKUP(AC21, price_lookup_table!$C:$C, price_lookup_table!$B:$B), "") -> Self Pay
A22: ALV | B22: 45679 | C22: 45664 | D22: screening | E22: Booked | F22: Kermie | G22: Snodin | H22: 488 Talisman Hill | I22: Room 885 | M22: SL5 7PF | N22: ksnodink@mediafire.com | O22: male | P22: 16831 | Q22: =DATEDIF(P22,B22,"Y") -> 78 | R22: 5FBC9C1A | S22: 447775816261 | T22: Advanced | V22: {=IFERROR( _xlfn.XLOOKUP(1, (tblPrices[Prefix]=$AC22)*(tblPrices[Product Code]=$T22), tblPrices[Price] ), 0 ) + IF(ISNUMBER(SEARCH("Mammogram",$U22)), IFERROR(_xlfn.XLOOKUP(1,(tblPrices[Prefix]=$AC22)*(tblPrices[Product Code]="Mammogram"),tblPrices[Price]),0), 0 ) + IF(ISNUMBER(SEARCH("PSA",$U22)), IFERROR(_xlfn.XLOOKUP(1,(tblPrices[Prefix]=$AC22)*(tblPrices[Product Code]="PSA"),tblPrices[Price]),0), 0 )} -> 517.5 | W22: dispatched | X22: paid,fasting,online,ecg_uploaded,viewed_online | Z22: 19086541 | AA22: T71 | AB22: {=_xlfn.LET(_xlpm.pc, UPPER(TRIM(M22)), LEFT(_xlpm.pc, MIN(FIND({0,1,2,3,4,5,6,7,8,9}, _xlpm.pc&"0123456789"))-1))} -> SL | AC22: T71 | AD22: =VLOOKUP(AB22, postcode_table!A:B, 2, FALSE) -> Slough | AE22: =IFERROR(_xlfn.XLOOKUP(AC22, price_lookup_table!$C:$C, price_lookup_table!$B:$B), "") -> Corporate
A23: RID | B23: 45680 | C23: 45671 | D23: screening | E23: Booked | F23: Arri | G23: Stollenbecker | H23: 511 Melvin Hill | I23: Room 1639 | M23: BS27 3GL | N23: astollenbeckerl@plala.or.jp | O23: male | P23: 16146 | Q23: =DATEDIF(P23,B23,"Y") -> 80 | R23: 204EFB6E | S23: 447776410747 | T23: Advanced | V23: {=IFERROR( _xlfn.XLOOKUP(1, (tblPrices[Prefix]=$AC23)*(tblPrices[Product Code]=$T23), tblPrices[Price] ), 0 ) + IF(ISNUMBER(SEARCH("Mammogram",$U23)), IFERROR(_xlfn.XLOOKUP(1,(tblPrices[Prefix]=$AC23)*(tblPrices[Product Code]="Mammogram"),tblPrices[Price]),0), 0 ) + IF(ISNUMBER(SEARCH("PSA",$U23)), IFERROR(_xlfn.XLOOKUP(1,(tblPrices[Prefix]=$AC23)*(tblPrices[Product Code]="PSA"),tblPrices[Price]),0), 0 )} -> 517.5 | W23: dispatched | X23: paid,fasting,online,viewed_online | Z23: 22016359 | AA23: T71 | AB23: {=_xlfn.LET(_xlpm.pc, UPPER(TRIM(M23)), LEFT(_xlpm.pc, MIN(FIND({0,1,2,3,4,5,6,7,8,9}, _xlpm.pc&"0123456789"))-1))} -> BS | AC23: T71 | AD23: =VLOOKUP(AB23, postcode_table!A:B, 2, FALSE) -> Bristol | AE23: =IFERROR(_xlfn.XLOOKUP(AC23, price_lookup_table!$C:$C, price_lookup_table!$B:$B), "") -> Corporate
A24: GAR | B24: 45680 | C24: 45674 | D24: screening | E24: Booked | F24: Kimmie | G24: Vince | H24: 799 Hayes Drive | I24: Room 1685 | M24: HA5 5HX | N24: kvincem@fema.gov | O24: female | P24: 17688 | Q24: =DATEDIF(P24,B24,"Y") -> 76 | R24: 1BC710C0 | S24: 447967366230 | T24: Advanced | V24: {=IFERROR( _xlfn.XLOOKUP(1, (tblPrices[Prefix]=$AC24)*(tblPrices[Product Code]=$T24), tblPrices[Price] ), 0 ) + IF(ISNUMBER(SEARCH("Mammogram",$U24)), IFERROR(_xlfn.XLOOKUP(1,(tblPrices[Prefix]=$AC24)*(tblPrices[Product Code]="Mammogram"),tblPrices[Price]),0), 0 ) + IF(ISNUMBER(SEARCH("PSA",$U24)), IFERROR(_xlfn.XLOOKUP(1,(tblPrices[Prefix]=$AC24)*(tblPrices[Product Code]="PSA"),tblPrices[Price]),0), 0 )} -> 517.5 | W24: dispatched | X24: viewed_online,paid,fasting,green,online | Z24: 16696280 | AA24: T71 | AB24: {=_xlfn.LET(_xlpm.pc, UPPER(TRIM(M24)), LEFT(_xlpm.pc, MIN(FIND({0,1,2,3,4,5,6,7,8,9}, _xlpm.pc&"0123456789"))-1))} -> HA | AC24: T71 | AD24: =VLOOKUP(AB24, postcode_table!A:B, 2, FALSE) -> Harrow | AE24: =IFERROR(_xlfn.XLOOKUP(AC24, price_lookup_table!$C:$C, price_lookup_table!$B:$B), "") -> Corporate
A25: RUN | B25: 45680 | C25: 45663 | D25: screening | E25: Booked | F25: Ludovika | G25: Botwood | H25: 8 Westend Alley | I25: PO Box 62728 | M25: TW11 9HQ | N25: lbotwoodn@digg.com | O25: female | P25: 26916 | Q25: =DATEDIF(P25,B25,"Y") -> 51 | R25: A7A2D9D7 | S25: 447957371753 | T25: Advanced Plus | V25: {=IFERROR( _xlfn.XLOOKUP(1, (tblPrices[Prefix]=$AC25)*(tblPrices[Product Code]=$T25), tblPrices[Price] ), 0 ) + IF(ISNUMBER(SEARCH("Mammogram",$U25)), IFERROR(_xlfn.XLOOKUP(1,(tblPrices[Prefix]=$AC25)*(tblPrices[Product Code]="Mammogram"),tblPrices[Price]),0), 0 ) + IF(ISNUMBER(SEARCH("PSA",$U25)), IFERROR(_xlfn.XLOOKUP(1,(tblPrices[Prefix]=$AC25)*(tblPrices[Product Code]="PSA"),tblPrices[Price]),0), 0 )} -> 693.38 | W25: dispatched | X25: paid,fasting,amber,online,ecg_uploaded,viewed_online | Z25: 22004414 | AA25: T71 | AB25: {=_xlfn.LET(_xlpm.pc, UPPER(TRIM(M25)), LEFT(_xlpm.pc, MIN(FIND({0,1,2,3,4,5,6,7,8,9}, _xlpm.pc&"0123456789"))-1))} -> TW | AC25: T71 | AD25: =VLOOKUP(AB25, postcode_table!A:B, 2, FALSE) -> Twickenham | AE25: =IFERROR(_xlfn.XLOOKUP(AC25, price_lookup_table!$C:$C, price_lookup_table!$B:$B), "") -> Corporate
A26: RHB | B26: 45680 | C26: 45677 | D26: screening | E26: Booked | F26: Fairleigh | G26: Sadlier | H26: 2 6th Lane | I26: 14th Floor | M26: IV2 5AZ | N26: fsadliero@github.com | O26: male | P26: 27291 | Q26: =DATEDIF(P26,B26,"Y") -> 50 | R26: 0BB10AE6 | S26: 447801289103 | T26: Advanced | V26: {=IFERROR( _xlfn.XLOOKUP(1, (tblPrices[Prefix]=$AC26)*(tblPrices[Product Code]=$T26), tblPrices[Price] ), 0 ) + IF(ISNUMBER(SEARCH("Mammogram",$U26)), IFERROR(_xlfn.XLOOKUP(1,(tblPrices[Prefix]=$AC26)*(tblPrices[Product Code]="Mammogram"),tblPrices[Price]),0), 0 ) + IF(ISNUMBER(SEARCH("PSA",$U26)), IFERROR(_xlfn.XLOOKUP(1,(tblPrices[Prefix]=$AC26)*(tblPrices[Product Code]="PSA"),tblPrices[Price]),0), 0 )} -> 517.5 | W26: dispatched | X26: paid,phone_call_required,fasting,online,ecg_uploaded,viewed_online | Z26: 18668675 | AA26: T71 | AB26: {=_xlfn.LET(_xlpm.pc, UPPER(TRIM(M26)), LEFT(_xlpm.pc, MIN(FIND({0,1,2,3,4,5,6,7,8,9}, _xlpm.pc&"0123456789"))-1))} -> IV | AC26: T71 | AD26: =VLOOKUP(AB26, postcode_table!A:B, 2, FALSE) -> Inverness | AE26: =IFERROR(_xlfn.XLOOKUP(AC26, price_lookup_table!$C:$C, price_lookup_table!$B:$B), "") -> Corporate
A27: GAR | B27: 45681 | C27: 45674 | D27: screening | E27: Booked | F27: Nickola | G27: McKeaney | H27: 4 Stephen Alley | I27: Apt 1786 | M27: HA5 5HX | N27: nmckeaneyp@goo.ne.jp | O27: male | P27: 35531 | Q27: =DATEDIF(P27,B27,"Y") -> 27 | R27: 1020473D | S27: 447973819691 | T27: Advanced | V27: {=IFERROR( _xlfn.XLOOKUP(1, (tblPrices[Prefix]=$AC27)*(tblPrices[Product Code]=$T27), tblPrices[Price] ), 0 ) + IF(ISNUMBER(SEARCH("Mammogram",$U27)), IFERROR(_xlfn.XLOOKUP(1,(tblPrices[Prefix]=$AC27)*(tblPrices[Product Code]="Mammogram"),tblPrices[Price]),0), 0 ) + IF(ISNUMBER(SEARCH("PSA",$U27)), IFERROR(_xlfn.XLOOKUP(1,(tblPrices[Prefix]=$AC27)*(tblPrices[Product Code]="PSA"),tblPrices[Price]),0), 0 )} -> 517.5 | W27: dispatched | X27: rescheduled,paid,fasting,amber,online,viewed_online | Z27: 16005325 | AA27: T71 | AB27: {=_xlfn.LET(_xlpm.pc, UPPER(TRIM(M27)), LEFT(_xlpm.pc, MIN(FIND({0,1,2,3,4,5,6,7,8,9}, _xlpm.pc&"0123456789"))-1))} -> HA | AC27: T71 | AD27: =VLOOKUP(AB27, postcode_table!A:B, 2, FALSE) -> Harrow | AE27: =IFERROR(_xlfn.XLOOKUP(AC27, price_lookup_table!$C:$C, price_lookup_table!$B:$B), "") -> Corporate
A28: ALX | B28: 45681 | C28: 45663 | D28: screening | E28: Booked | F28: Kirsten | G28: Stogill | H28: 871 Coolidge Park | I28: Suite 28 | M28: WA16 8EJ | N28: kstogillq@slashdot.org | O28: male | P28: 26970 | Q28: =DATEDIF(P28,B28,"Y") -> 51 | R28: 82EFDEB8 | S28: 447904092231 | T28: Advanced | V28: {=IFERROR( _xlfn.XLOOKUP(1, (tblPrices[Prefix]=$AC28)*(tblPrices[Product Code]=$T28), tblPrices[Price] ), 0 ) + IF(ISNUMBER(SEARCH("Mammogram",$U28)), IFERROR(_xlfn.XLOOKUP(1,(tblPrices[Prefix]=$AC28)*(tblPrices[Product Code]="Mammogram"),tblPrices[Price]),0), 0 ) + IF(ISNUMBER(SEARCH("PSA",$U28)), IFERROR(_xlfn.XLOOKUP(1,(tblPrices[Prefix]=$AC28)*(tblPrices[Product Code]="PSA"),tblPrices[Price]),0), 0 )} -> 517.5 | W28: dispatched | X28: paid,fasting,online,ecg_uploaded,viewed_online | Z28: 16916934 | AA28: T71 | AB28: {=_xlfn.LET(_xlpm.pc, UPPER(TRIM(M28)), LEFT(_xlpm.pc, MIN(FIND({0,1,2,3,4,5,6,7,8,9}, _xlpm.pc&"0123456789"))-1))} -> WA | AC28: T71 | AD28: =VLOOKUP(AB28, postcode_table!A:B, 2, FALSE) -> Warrington | AE28: =IFERROR(_xlfn.XLOOKUP(AC28, price_lookup_table!$C:$C, price_lookup_table!$B:$B), "") -> Corporate
A29: ALB | B29: 45681 | C29: 45665 | D29: screening | E29: Booked | F29: Fabe | G29: Agdahl | H29: 1749 Jana Point | I29: Suite 45 | M29: AB15 8GW | N29: fagdahlr@alibaba.com | O29: male | P29: 28663 | Q29: =DATEDIF(P29,B29,"Y") -> 46 | R29: F01C8028 | S29: 447865198512 | T29: Advanced | V29: {=IFERROR( _xlfn.XLOOKUP(1, (tblPrices[Prefix]=$AC29)*(tblPrices[Product Code]=$T29), tblPrices[Price] ), 0 ) + IF(ISNUMBER(SEARCH("Mammogram",$U29)), IFERROR(_xlfn.XLOOKUP(1,(tblPrices[Prefix]=$AC29)*(tblPrices[Product Code]="Mammogram"),tblPrices[Price]),0), 0 ) + IF(ISNUMBER(SEARCH("PSA",$U29)), IFERROR(_xlfn.XLOOKUP(1,(tblPrices[Prefix]=$AC29)*(tblPrices[Product Code]="PSA"),tblPrices[Price]),0), 0 )} -> 517.5 | W29: dispatched | X29: paid,fasting | Z29: 20618377 | AA29: T71 | AB29: {=_xlfn.LET(_xlpm.pc, UPPER(TRIM(M29)), LEFT(_xlpm.pc, MIN(FIND({0,1,2,3,4,5,6,7,8,9}, _xlpm.pc&"0123456789"))-1))} -> AB | AC29: T71 | AD29: =VLOOKUP(AB29, postcode_table!A:B, 2, FALSE) -> Aberdeen | AE29: =IFERROR(_xlfn.XLOOKUP(AC29, price_lookup_table!$C:$C, price_lookup_table!$B:$B), "") -> Corporate
A30: SLO | B30: 45684 | C30: 45659 | D30: screening | E30: Booked | F30: Redford | G30: Charnock | H30: 333 Kingsford Alley | I30: 15th Floor | M30: CR3 6JF | N30: rcharnocks@bbc.co.uk | O30: male | P30: 36810 | Q30: =DATEDIF(P30,B30,"Y") -> 24 | R30: 07452CA1 | S30: 447724255886 | T30: Advanced | V30: {=IFERROR( _xlfn.XLOOKUP(1, (tblPrices[Prefix]=$AC30)*(tblPrices[Product Code]=$T30), tblPrices[Price] ), 0 ) + IF(ISNUMBER(SEARCH("Mammogram",$U30)), IFERROR(_xlfn.XLOOKUP(1,(tblPrices[Prefix]=$AC30)*(tblPrices[Product Code]="Mammogram"),tblPrices[Price]),0), 0 ) + IF(ISNUMBER(SEARCH("PSA",$U30)), IFERROR(_xlfn.XLOOKUP(1,(tblPrices[Prefix]=$AC30)*(tblPrices[Product Code]="PSA"),tblPrices[Price]),0), 0 )} -> 517.5 | W30: dispatched | X30: rescheduled,paid,fasting,online,viewed_online | Z30: 21561378 | AA30: T71 | AB30: {=_xlfn.LET(_xlpm.pc, UPPER(TRIM(M30)), LEFT(_xlpm.pc, MIN(FIND({0,1,2,3,4,5,6,7,8,9}, _xlpm.pc&"0123456789"))-1))} -> CR | AC30: T71 | AD30: =VLOOKUP(AB30, postcode_table!A:B, 2, FALSE) -> Croydon | AE30: =IFERROR(_xlfn.XLOOKUP(AC30, price_lookup_table!$C:$C, price_lookup_table!$B:$B), "") -> Corporate
A31: LIH | B31: 45684 | C31: 45664 | D31: screening | E31: Booked | F31: Artemus | G31: Teacy | H31: 363 Ramsey Trail | I31: PO Box 48667 | M31: EC1M 5UG | N31: ateacyt@g.co | O31: male | P31: 15933 | Q31: =DATEDIF(P31,B31,"Y") -> 81 | R31: 09D45ABC | S31: 447741766348 | T31: Advanced | V31: {=IFERROR( _xlfn.XLOOKUP(1, (tblPrices[Prefix]=$AC31)*(tblPrices[Product Code]=$T31), tblPrices[Price] ), 0 ) + IF(ISNUMBER(SEARCH("Mammogram",$U31)), IFERROR(_xlfn.XLOOKUP(1,(tblPrices[Prefix]=$AC31)*(tblPrices[Product Code]="Mammogram"),tblPrices[Price]),0), 0 ) + IF(ISNUMBER(SEARCH("PSA",$U31)), IFERROR(_xlfn.XLOOKUP(1,(tblPrices[Prefix]=$AC31)*(tblPrices[Product Code]="PSA"),tblPrices[Price]),0), 0 )} -> 517.5 | W31: dispatched | X31: paid,fasting,online,viewed_online | Z31: 22007237 | AA31: T71 | AB31: {=_xlfn.LET(_xlpm.pc, UPPER(TRIM(M31)), LEFT(_xlpm.pc, MIN(FIND({0,1,2,3,4,5,6,7,8,9}, _xlpm.pc&"0123456789"))-1))} -> EC | AC31: T71 | AD31: =VLOOKUP(AB31, postcode_table!A:B, 2, FALSE) -> East Central London | AE31: =IFERROR(_xlfn.XLOOKUP(AC31, price_lookup_table!$C:$C, price_lookup_table!$B:$B), "") -> Corporate
A32: MNR | B32: 45684 | C32: 45660 | D32: screening | E32: Booked | F32: Ferdinande | G32: Jozaitis | H32: 5 Brown Parkway | I32: Suite 68 | M32: SG4 9PN | N32: fjozaitisu@topsy.com | O32: female | P32: 35439 | Q32: =DATEDIF(P32,B32,"Y") -> 28 | R32: 5F17E637 | S32: 447881658156 | T32: Advanced | V32: {=IFERROR( _xlfn.XLOOKUP(1, (tblPrices[Prefix]=$AC32)*(tblPrices[Product Code]=$T32), tblPrices[Price] ), 0 ) + IF(ISNUMBER(SEARCH("Mammogram",$U32)), IFERROR(_xlfn.XLOOKUP(1,(tblPrices[Prefix]=$AC32)*(tblPrices[Product Code]="Mammogram"),tblPrices[Price]),0), 0 ) + IF(ISNUMBER(SEARCH("PSA",$U32)), IFERROR(_xlfn.XLOOKUP(1,(tblPrices[Prefix]=$AC32)*(tblPrices[Product Code]="PSA"),tblPrices[Price]),0), 0 )} -> 543 | W32: dispatched | X32: paid,fasting,online,ecg_uploaded,viewed_online | Z32: 22003699 | AA32: AXAMEMBER | AB32: {=_xlfn.LET(_xlpm.pc, UPPER(TRIM(M32)), LEFT(_xlpm.pc, MIN(FIND({0,1,2,3,4,5,6,7,8,9}, _xlpm.pc&"0123456789"))-1))} -> SG | AC32: =LEFT(AA32, 3) -> AXA | AD32: =VLOOKUP(AB32, postcode_table!A:B, 2, FALSE) -> Stevenage | AE32: =IFERROR(_xlfn.XLOOKUP(AC32, price_lookup_table!$C:$C, price_lookup_table!$B:$B), "") -> Self Pay
A33: MNR | B33: 45684 | C33: 45660 | D33: screening | E33: Booked | F33: Manuel | G33: De Malchar | H33: 6 Northwestern Place | I33: Room 1879 | M33: SG4 9PN | N33: mdemalcharv@admin.ch | O33: male | P33: 31882 | Q33: =DATEDIF(P33,B33,"Y") -> 37 | R33: A2781577 | S33: 447890316923 | T33: Advanced | V33: {=IFERROR( _xlfn.XLOOKUP(1, (tblPrices[Prefix]=$AC33)*(tblPrices[Product Code]=$T33), tblPrices[Price] ), 0 ) + IF(ISNUMBER(SEARCH("Mammogram",$U33)), IFERROR(_xlfn.XLOOKUP(1,(tblPrices[Prefix]=$AC33)*(tblPrices[Product Code]="Mammogram"),tblPrices[Price]),0), 0 ) + IF(ISNUMBER(SEARCH("PSA",$U33)), IFERROR(_xlfn.XLOOKUP(1,(tblPrices[Prefix]=$AC33)*(tblPrices[Product Code]="PSA"),tblPrices[Price]),0), 0 )} -> 543 | W33: dispatched | X33: paid,fasting,online,ecg_uploaded,viewed_online | Z33: 22003190 | AA33: AXAMEMBER | AB33: {=_xlfn.LET(_xlpm.pc, UPPER(TRIM(M33)), LEFT(_xlpm.pc, MIN(FIND({0,1,2,3,4,5,6,7,8,9}, _xlpm.pc&"0123456789"))-1))} -> SG | AC33: =LEFT(AA33, 3) -> AXA | AD33: =VLOOKUP(AB33, postcode_table!A:B, 2, FALSE) -> Stevenage | AE33: =IFERROR(_xlfn.XLOOKUP(AC33, price_lookup_table!$C:$C, price_lookup_table!$B:$B), "") -> Self Pay
A34: SYC | B34: 45684 | C34: 45671 | D34: screening | E34: Booked | F34: Sascha | G34: Syde | H34: 4868 Vidon Park | I34: Suite 38 | M34: W12 9RZ | N34: ssydew@google.es | O34: female | P34: 15487 | Q34: =DATEDIF(P34,B34,"Y") -> 82 | R34: A2B1E98C | S34: 447947157800 | T34: Advanced | V34: {=IFERROR( _xlfn.XLOOKUP(1, (tblPrices[Prefix]=$AC34)*(tblPrices[Product Code]=$T34), tblPrices[Price] ), 0 ) + IF(ISNUMBER(SEARCH("Mammogram",$U34)), IFERROR(_xlfn.XLOOKUP(1,(tblPrices[Prefix]=$AC34)*(tblPrices[Product Code]="Mammogram"),tblPrices[Price]),0), 0 ) + IF(ISNUMBER(SEARCH("PSA",$U34)), IFERROR(_xlfn.XLOOKUP(1,(tblPrices[Prefix]=$AC34)*(tblPrices[Product Code]="PSA"),tblPrices[Price]),0), 0 )} -> 507.53 | W34: dispatched | X34: rescheduled,paid,fasting,red,online,viewed_online | Z34: 22003140 | AA34: T35 | AB34: {=_xlfn.LET(_xlpm.pc, UPPER(TRIM(M34)), LEFT(_xlpm.pc, MIN(FIND({0,1,2,3,4,5,6,7,8,9}, _xlpm.pc&"0123456789"))-1))} -> W | AC34: T35 | AD34: =VLOOKUP(AB34, postcode_table!A:B, 2, FALSE) -> West London | AE34: =IFERROR(_xlfn.XLOOKUP(AC34, price_lookup_table!$C:$C, price_lookup_table!$B:$B), "") -> Corporate Flex
A35: ALV | B35: 45684 | C35: 45678 | D35: screening | E35: Booked | F35: Reid | G35: Aizlewood | H35: 6702 Sugar Plaza | I35: Room 855 | M35: GU34 3AW | N35: raizlewoodx@bing.com | O35: male | P35: 32387 | Q35: =DATEDIF(P35,B35,"Y") -> 36 | R35: 537FD23A | S35: 447774295485 | T35: Advanced Plus | V35: {=IFERROR( _xlfn.XLOOKUP(1, (tblPrices[Prefix]=$AC35)*(tblPrices[Product Code]=$T35), tblPrices[Price] ), 0 ) + IF(ISNUMBER(SEARCH("Mammogram",$U35)), IFERROR(_xlfn.XLOOKUP(1,(tblPrices[Prefix]=$AC35)*(tblPrices[Product Code]="Mammogram"),tblPrices[Price]),0), 0 ) + IF(ISNUMBER(SEARCH("PSA",$U35)), IFERROR(_xlfn.XLOOKUP(1,(tblPrices[Prefix]=$AC35)*(tblPrices[Product Code]="PSA"),tblPrices[Price]),0), 0 )} -> 0 | W35: dispatched | X35: viewed_online,paid,fasting,online,ecg_uploaded | Z35: 19092667 | AA35: T35 | AB35: {=_xlfn.LET(_xlpm.pc, UPPER(TRIM(M35)), LEFT(_xlpm.pc, MIN(FIND({0,1,2,3,4,5,6,7,8,9}, _xlpm.pc&"0123456789"))-1))} -> GU | AC35: T35 | AD35: =VLOOKUP(AB35, postcode_table!A:B, 2, FALSE) -> Guildford | AE35: =IFERROR(_xlfn.XLOOKUP(AC35, price_lookup_table!$C:$C, price_lookup_table!$B:$B), "") -> Corporate Flex
A36: ALV | B36: 45684 | C36: 45659 | D36: screening | E36: Booked | F36: Fenelia | G36: Blaszczynski | H36: 015 Hollow Ridge Trail | I36: 13th Floor | M36: GU3 2BZ | N36: fblaszczynskiy@tamu.edu | O36: male | P36: 36214 | Q36: =DATEDIF(P36,B36,"Y") -> 25 | R36: 71F5D986 | S36: 447949399963 | T36: Advanced Plus | V36: {=IFERROR( _xlfn.XLOOKUP(1, (tblPrices[Prefix]=$AC36)*(tblPrices[Product Code]=$T36), tblPrices[Price] ), 0 ) + IF(ISNUMBER(SEARCH("Mammogram",$U36)), IFERROR(_xlfn.XLOOKUP(1,(tblPrices[Prefix]=$AC36)*(tblPrices[Product Code]="Mammogram"),tblPrices[Price]),0), 0 ) + IF(ISNUMBER(SEARCH("PSA",$U36)), IFERROR(_xlfn.XLOOKUP(1,(tblPrices[Prefix]=$AC36)*(tblPrices[Product Code]="PSA"),tblPrices[Price]),0), 0 )} -> 0 | W36: dispatched | X36: paid,fasting,amber,online,ecg_uploaded,viewed_online | Z36: 20595991 | AA36: T35 | AB36: {=_xlfn.LET(_xlpm.pc, UPPER(TRIM(M36)), LEFT(_xlpm.pc, MIN(FIND({0,1,2,3,4,5,6,7,8,9}, _xlpm.pc&"0123456789"))-1))} -> GU | AC36: T35 | AD36: =VLOOKUP(AB36, postcode_table!A:B, 2, FALSE) -> Guildford | AE36: =IFERROR(_xlfn.XLOOKUP(AC36, price_lookup_table!$C:$C, price_lookup_table!$B:$B), "") -> Corporate Flex
A37: CHI | B37: 45684 | C37: 45678 | D37: screening | E37: Booked | F37: Rosalie | G37: Berriman | H37: 06 6th Lane | I37: PO Box 75460 | M37: SL6 6SG | N37: rberrimanz@harvard.edu | O37: female | P37: 23348 | Q37: =DATEDIF(P37,B37,"Y") -> 61 | R37: 229203DC | S37: 447823559000 | T37: Advanced | V37: {=IFERROR( _xlfn.XLOOKUP(1, (tblPrices[Prefix]=$AC37)*(tblPrices[Product Code]=$T37), tblPrices[Price] ), 0 ) + IF(ISNUMBER(SEARCH("Mammogram",$U37)), IFERROR(_xlfn.XLOOKUP(1,(tblPrices[Prefix]=$AC37)*(tblPrices[Product Code]="Mammogram"),tblPrices[Price]),0), 0 ) + IF(ISNUMBER(SEARCH("PSA",$U37)), IFERROR(_xlfn.XLOOKUP(1,(tblPrices[Prefix]=$AC37)*(tblPrices[Product Code]="PSA"),tblPrices[Price]),0), 0 )} -> 507.53 | W37: dispatched | X37: paid,phone_call_required,fasting,online,ecg_uploaded,viewed_online | Z37: 10033314 | AA37: T35 | AB37: {=_xlfn.LET(_xlpm.pc, UPPER(TRIM(M37)), LEFT(_xlpm.pc, MIN(FIND({0,1,2,3,4,5,6,7,8,9}, _xlpm.pc&"0123456789"))-1))} -> SL | AC37: T35 | AD37: =VLOOKUP(AB37, postcode_table!A:B, 2, FALSE) -> Slough | AE37: =IFERROR(_xlfn.XLOOKUP(AC37, price_lookup_table!$C:$C, price_lookup_table!$B:$B), "") -> Corporate Flex
A38: ALV | B38: 45685 | C38: 45667 | D38: screening | E38: Booked | F38: Brynn | G38: Darrach | H38: 9 Village Place | I38: Suite 88 | M38: RH4 3NX | N38: bdarrach10@chronoengine.com | O38: male | P38: 35199 | Q38: =DATEDIF(P38,B38,"Y") -> 28 | R38: 6FFF4DAE | S38: 447912042116 | T38: Advanced Plus | V38: {=IFERROR( _xlfn.XLOOKUP(1, (tblPrices[Prefix]=$AC38)*(tblPrices[Product Code]=$T38), tblPrices[Price] ), 0 ) + IF(ISNUMBER(SEARCH("Mammogram",$U38)), IFERROR(_xlfn.XLOOKUP(1,(tblPrices[Prefix]=$AC38)*(tblPrices[Product Code]="Mammogram"),tblPrices[Price]),0), 0 ) + IF(ISNUMBER(SEARCH("PSA",$U38)), IFERROR(_xlfn.XLOOKUP(1,(tblPrices[Prefix]=$AC38)*(tblPrices[Product Code]="PSA"),tblPrices[Price]),0), 0 )} -> 0 | W38: dispatched | X38: viewed_online,paid,fasting,online,ecg_uploaded | Z38: 21764128 | AA38: T35 | AB38: {=_xlfn.LET(_xlpm.pc, UPPER(TRIM(M38)), LEFT(_xlpm.pc, MIN(FIND({0,1,2,3,4,5,6,7,8,9}, _xlpm.pc&"0123456789"))-1))} -> RH | AC38: T35 | AD38: =VLOOKUP(AB38, postcode_table!A:B, 2, FALSE) -> Redhill | AE38: =IFERROR(_xlfn.XLOOKUP(AC38, price_lookup_table!$C:$C, price_lookup_table!$B:$B), "") -> Corporate Flex
A39: BSE | B39: 45685 | C39: 45664 | D39: screening | E39: Booked | F39: Chelsey | G39: Brumhead | H39: 69066 Manufacturers Hill | I39: 17th Floor | M39: CO10 0QX | N39: cbrumhead11@yelp.com | O39: female | P39: 29739 | Q39: =DATEDIF(P39,B39,"Y") -> 43 | R39: 7F62DB78 | S39: 447940160976 | T39: Advanced | V39: {=IFERROR( _xlfn.XLOOKUP(1, (tblPrices[Prefix]=$AC39)*(tblPrices[Product Code]=$T39), tblPrices[Price] ), 0 ) + IF(ISNUMBER(SEARCH("Mammogram",$U39)), IFERROR(_xlfn.XLOOKUP(1,(tblPrices[Prefix]=$AC39)*(tblPrices[Product Code]="Mammogram"),tblPrices[Price]),0), 0 ) + IF(ISNUMBER(SEARCH("PSA",$U39)), IFERROR(_xlfn.XLOOKUP(1,(tblPrices[Prefix]=$AC39)*(tblPrices[Product Code]="PSA"),tblPrices[Price]),0), 0 )} -> 507.53 | W39: dispatched | X39: paid,fasting,online,viewed_online | Z39: 22006288 | AA39: T35 | AB39: {=_xlfn.LET(_xlpm.pc, UPPER(TRIM(M39)), LEFT(_xlpm.pc, MIN(FIND({0,1,2,3,4,5,6,7,8,9}, _xlpm.pc&"0123456789"))-1))} -> CO | AC39: T35 | AD39: =VLOOKUP(AB39, postcode_table!A:B, 2, FALSE) -> Colchester | AE39: =IFERROR(_xlfn.XLOOKUP(AC39, price_lookup_table!$C:$C, price_lookup_table!$B:$B), "") -> Corporate Flex
A40: ALB | B40: 45685 | C40: 45664 | D40: screening | E40: Booked | F40: Eduino | G40: Allcott | H40: 13 Redwing Court | I40: 15th Floor | M40: IV1 3YG | N40: eallcott12@amazon.de | O40: female | P40: 29883 | Q40: =DATEDIF(P40,B40,"Y") -> 43 | R40: 6414EEA3 | S40: 447790171844 | T40: Advanced | V40: {=IFERROR( _xlfn.XLOOKUP(1, (tblPrices[Prefix]=$AC40)*(tblPrices[Product Code]=$T40), tblPrices[Price] ), 0 ) + IF(ISNUMBER(SEARCH("Mammogram",$U40)), IFERROR(_xlfn.XLOOKUP(1,(tblPrices[Prefix]=$AC40)*(tblPrices[Product Code]="Mammogram"),tblPrices[Price]),0), 0 ) + IF(ISNUMBER(SEARCH("PSA",$U40)), IFERROR(_xlfn.XLOOKUP(1,(tblPrices[Prefix]=$AC40)*(tblPrices[Product Code]="PSA"),tblPrices[Price]),0), 0 )} -> 507.53 | W40: dispatched | X40: paid,fasting,online,viewed_online | Z40: 22006569 | AA40: T35 | AB40: {=_xlfn.LET(_xlpm.pc, UPPER(TRIM(M40)), LEFT(_xlpm.pc, MIN(FIND({0,1,2,3,4,5,6,7,8,9}, _xlpm.pc&"0123456789"))-1))} -> IV | AC40: T35 | AD40: =VLOOKUP(AB40, postcode_table!A:B, 2, FALSE) -> Inverness | AE40: =IFERROR(_xlfn.XLOOKUP(AC40, price_lookup_table!$C:$C, price_lookup_table!$B:$B), "") -> Corporate Flex
...

Sheet price_lookup_table
A2: Client Name | B2: Client Type | C2: Prefix | D2: Product Code | E2: Price | F2: Price Agreement Effective From,
A3: 3D Leisure | B3: Self Pay | C3: R98 | D3: Essential | E3: 184.5 | F3: 45658
A4: 3D Leisure | B4: Self Pay | C4: R98 | D4: Select | E4: 357.38 | F4: 45658
A5: 3D Leisure | B5: Self Pay | C5: R98 | D5: Advanced | E5: 543.38 | F5: 45658
A6: 3D Leisure | B6: Self Pay | C6: R98 | D6: Advanced Plus | E6: 727.88 | F6: 45658
A7: 3D Leisure | B7: Self Pay | C7: R98 | D7: Mammogram | E7: 147 | F7: 45658
A8: 3D Leisure | B8: Self Pay | C8: R98 | D8: PSA | E8: 112 | F8: 45658
A9: A.I.A.C.E. | B9: Self Pay | C9: AIA | D9: Advanced | E9: 493 | F9: 45657
A10: A.I.A.C.E. | B10: Self Pay | C10: AIA | D10: Advanced Plus | E10: 660 | F10: 45657
A11: A.I.A.C.E. | B11: Self Pay | C11: AIA | D11: Mammogram | E11: 128 | F11: 45657
A12: A.I.A.C.E. | B12: Self Pay | C12: AIA | D12: PSA | E12: 98 | F12: 45657
A13: Airpark Service Ltd – Birmingham | B13: Corporate | C13: M06 | D13: Select | E13: 324 | F13: 45139
A14: Airpark Service Ltd – Birmingham | B14: Corporate | C14: M06 | D14: Mammogram | E14: 128 | F14: 45139
... A193: F. R. Monkhouse Ltd | B193: Corporate | C193: UJ4 | D193: Mammogram | E193: 102 | F193: 44197
A194: Fedcap | B194: Corporate | C194: UL3 | D194: Select | E194: 357 | F194: REN
A195: Fedcap | B195: Corporate | C195: UL3 | D195: Advanced | E195: 543 | F195: REN
A196: Fedcap | B196: Corporate | C196: UL3 | D196: Advanced Plus | E196: 728 | F196: REN
A197: Fedcap | B197: Corporate | C197: UL3 | D197: Mammogram | E197: 147 | F197: REN
A198: Fedcap | B198: Corporate | C198: UL3 | D198: PSA | E198: 112 | F198: REN
A199: First Rate Exchange Services Ltd | B199: Corporate | C199: U37 | D199: Advanced | E199: 586.5 | F199: 45444
A200: First Rate Exchange Services Ltd | B200: Corporate | C200: U37 | D200: Advanced Plus | E200: 786 | F200: 45444
A201: First Rate Exchange Services Ltd | B201: Corporate | C201: U37 | D201: Mammogram | E201: 140 | F201: 45444
A202: Fluor Ltd F | B202: Corporate | C202: MD7 | D202: Advanced | E202: 493 | F202: 45292
A203: Fluor Ltd F | B203: Corporate | C203: MD7 | D203: Advanced Plus | E203: 660 | F203: 45292
A204: Fluor Ltd F | B204: Corporate | C204: MD7 | D204: Mammogram | E204: 128 | F204: 45292
A205: Forester Holdings | B205: Corporate | C205: U01 | D205: Advanced | E205: 430 | F205: 43007
A206: Forester Holdings | B206: Corporate | C206: U01 | D206: Advanced Plus | E206: 575 | F206: 43007
A207: Forester Holdings | B207: Corporate | C207: U01 | D207: Mammogram | E207: 98 | F207: 43007
A208: Fresca Group Ltd | B208: Corporate | C208: MT7 | D208: Advanced | E208: 517.5 | F208: 45566
A209: Fresca Group Ltd | B209: Corporate | C209: MT7 | D209: Advanced Plus | E209: 693 | F209: 45566
A210: Fresca Group Ltd | B210: Corporate | C210: MT7 | D210: Mammogram | E210: 140 | F210: 45566
... A390: MAN Truck & Bus UK Ltd | B390: Corporate | C390: TU6 | D390: Mammogram | E390: 140 | F390: 45658
A391: Marchmont Investment | B391: Corporate | C391: SF2 | D391: Advanced | F391: 45901
A392: Marchmont Investment | B392: Corporate | C392: SF2 | D392: Advanced Plus | F392: 45901
A393: Medical Expense Consulting | B393: Corporate | C393: UA7 | D393: Essential | E393: 167.63 | F393: 45627
A394: Medical Expense Consulting | B394: Corporate | C394: UA7 | D394: Select | E394: 324.38 | F394: 45627
A395: Medical Expense Consulting | B395: Corporate | C395: UA7 | D395: Advanced | E395: 492.75 | F395: 45627
A396: Medical Expense Consulting | B396: Corporate | C396: UA7 | D396: Advanced Plus | E396: 660.38 | F396: 45627
A397: Medical Expense Consulting | B397: Corporate | C397: UA7 | D397: Mammogram | E397: 128 | F397: 45627
A398: Medical Expense Consulting | B398: Corporate | C398: UA7 | D398: PSA | E398: 98 | F398: 45627
...

Sheet postcode_table
A1: Column1 | B1: Column2
A2: Postcode area | B2: Postcode area name
A3: AB | B3: Aberdeen
A4: AL | B4: St Albans
A5: B | B5: Birmingham
A6: BA | B6: Bath
A7: BB | B7: Blackburn
A8: BD | B8: Bradford
A9: BH | B9: Bournemouth
A10: BL | B10: Bolton
A11: BN | B11: Brighton
A12: BR | B12: Bromley
... A123: ZE | B123: Lerwick
